/software/conda/envs/tensorflow/lib/python3.6/site-packages/tensorflow/python/framework/dtypes.py:516: FutureWarning: Passing (type, 1) or '1type' as a synonym of type is deprecated; in a future version of numpy, it will be understood as (type, (1,)) / '(1,)type'.
  _np_qint8 = np.dtype([("qint8", np.int8, 1)])
/software/conda/envs/tensorflow/lib/python3.6/site-packages/tensorflow/python/framework/dtypes.py:517: FutureWarning: Passing (type, 1) or '1type' as a synonym of type is deprecated; in a future version of numpy, it will be understood as (type, (1,)) / '(1,)type'.
  _np_quint8 = np.dtype([("quint8", np.uint8, 1)])
/software/conda/envs/tensorflow/lib/python3.6/site-packages/tensorflow/python/framework/dtypes.py:518: FutureWarning: Passing (type, 1) or '1type' as a synonym of type is deprecated; in a future version of numpy, it will be understood as (type, (1,)) / '(1,)type'.
  _np_qint16 = np.dtype([("qint16", np.int16, 1)])
/software/conda/envs/tensorflow/lib/python3.6/site-packages/tensorflow/python/framework/dtypes.py:519: FutureWarning: Passing (type, 1) or '1type' as a synonym of type is deprecated; in a future version of numpy, it will be understood as (type, (1,)) / '(1,)type'.
  _np_quint16 = np.dtype([("quint16", np.uint16, 1)])
/software/conda/envs/tensorflow/lib/python3.6/site-packages/tensorflow/python/framework/dtypes.py:520: FutureWarning: Passing (type, 1) or '1type' as a synonym of type is deprecated; in a future version of numpy, it will be understood as (type, (1,)) / '(1,)type'.
  _np_qint32 = np.dtype([("qint32", np.int32, 1)])
/software/conda/envs/tensorflow/lib/python3.6/site-packages/tensorflow/python/framework/dtypes.py:525: FutureWarning: Passing (type, 1) or '1type' as a synonym of type is deprecated; in a future version of numpy, it will be understood as (type, (1,)) / '(1,)type'.
  np_resource = np.dtype([("resource", np.ubyte, 1)])
/software/conda/envs/tensorflow/lib/python3.6/site-packages/tensorboard/compat/tensorflow_stub/dtypes.py:541: FutureWarning: Passing (type, 1) or '1type' as a synonym of type is deprecated; in a future version of numpy, it will be understood as (type, (1,)) / '(1,)type'.
  _np_qint8 = np.dtype([("qint8", np.int8, 1)])
/software/conda/envs/tensorflow/lib/python3.6/site-packages/tensorboard/compat/tensorflow_stub/dtypes.py:542: FutureWarning: Passing (type, 1) or '1type' as a synonym of type is deprecated; in a future version of numpy, it will be understood as (type, (1,)) / '(1,)type'.
  _np_quint8 = np.dtype([("quint8", np.uint8, 1)])
/software/conda/envs/tensorflow/lib/python3.6/site-packages/tensorboard/compat/tensorflow_stub/dtypes.py:543: FutureWarning: Passing (type, 1) or '1type' as a synonym of type is deprecated; in a future version of numpy, it will be understood as (type, (1,)) / '(1,)type'.
  _np_qint16 = np.dtype([("qint16", np.int16, 1)])
/software/conda/envs/tensorflow/lib/python3.6/site-packages/tensorboard/compat/tensorflow_stub/dtypes.py:544: FutureWarning: Passing (type, 1) or '1type' as a synonym of type is deprecated; in a future version of numpy, it will be understood as (type, (1,)) / '(1,)type'.
  _np_quint16 = np.dtype([("quint16", np.uint16, 1)])
/software/conda/envs/tensorflow/lib/python3.6/site-packages/tensorboard/compat/tensorflow_stub/dtypes.py:545: FutureWarning: Passing (type, 1) or '1type' as a synonym of type is deprecated; in a future version of numpy, it will be understood as (type, (1,)) / '(1,)type'.
  _np_qint32 = np.dtype([("qint32", np.int32, 1)])
/software/conda/envs/tensorflow/lib/python3.6/site-packages/tensorboard/compat/tensorflow_stub/dtypes.py:550: FutureWarning: Passing (type, 1) or '1type' as a synonym of type is deprecated; in a future version of numpy, it will be understood as (type, (1,)) / '(1,)type'.
  np_resource = np.dtype([("resource", np.ubyte, 1)])
Traceback (most recent call last):
  File "/software/conda/envs/tensorflow/lib/python3.6/site-packages/tensorflow/python/client/session.py", line 1356, in _do_call
    return fn(*args)
  File "/software/conda/envs/tensorflow/lib/python3.6/site-packages/tensorflow/python/client/session.py", line 1341, in _run_fn
    options, feed_dict, fetch_list, target_list, run_metadata)
  File "/software/conda/envs/tensorflow/lib/python3.6/site-packages/tensorflow/python/client/session.py", line 1429, in _call_tf_sessionrun
    run_metadata)
tensorflow.python.framework.errors_impl.UnknownError: 2 root error(s) found.
  (0) Unknown: Failed to get convolution algorithm. This is probably because cuDNN failed to initialize, so try looking to see if a warning log message was printed above.
	 [[{{node 3d_conv/conv3d_1/Conv3D}}]]
  (1) Unknown: Failed to get convolution algorithm. This is probably because cuDNN failed to initialize, so try looking to see if a warning log message was printed above.
	 [[{{node 3d_conv/conv3d_1/Conv3D}}]]
	 [[2d_conv/strided_slice_2/_1163]]
0 successful operations.
0 derived errors ignored.

During handling of the above exception, another exception occurred:

Traceback (most recent call last):
  File "/home/ajasja/scripts/LocalAccuracyPredictor/ErrorPredictor.py", line 244, in <module>
    main()
  File "/home/ajasja/scripts/LocalAccuracyPredictor/ErrorPredictor.py", line 192, in main
    noEnsemble=args.noEnsemble)
  File "/home/ajasja/scripts/LocalAccuracyPredictor/pyErrorPred/predict.py", line 99, in predict
    lddt, estogram, mask = model.predict2(batch)
  File "/home/ajasja/scripts/LocalAccuracyPredictor/pyErrorPred/model.py", line 391, in predict2
    return self.sesh.run(operations, feed_dict=feed_dict)
  File "/software/conda/envs/tensorflow/lib/python3.6/site-packages/tensorflow/python/client/session.py", line 950, in run
    run_metadata_ptr)
  File "/software/conda/envs/tensorflow/lib/python3.6/site-packages/tensorflow/python/client/session.py", line 1173, in _run
    feed_dict_tensor, options, run_metadata)
  File "/software/conda/envs/tensorflow/lib/python3.6/site-packages/tensorflow/python/client/session.py", line 1350, in _do_run
    run_metadata)
  File "/software/conda/envs/tensorflow/lib/python3.6/site-packages/tensorflow/python/client/session.py", line 1370, in _do_call
    raise type(e)(node_def, op, message)
tensorflow.python.framework.errors_impl.UnknownError: 2 root error(s) found.
  (0) Unknown: Failed to get convolution algorithm. This is probably because cuDNN failed to initialize, so try looking to see if a warning log message was printed above.
	 [[node 3d_conv/conv3d_1/Conv3D (defined at home/ajasja/scripts/LocalAccuracyPredictor/pyErrorPred/model.py:98) ]]
  (1) Unknown: Failed to get convolution algorithm. This is probably because cuDNN failed to initialize, so try looking to see if a warning log message was printed above.
	 [[node 3d_conv/conv3d_1/Conv3D (defined at home/ajasja/scripts/LocalAccuracyPredictor/pyErrorPred/model.py:98) ]]
	 [[2d_conv/strided_slice_2/_1163]]
0 successful operations.
0 derived errors ignored.

Errors may have originated from an input operation.
Input Source operations connected to node 3d_conv/conv3d_1/Conv3D:
 3d_conv/conv3d/Conv3D (defined at home/ajasja/scripts/LocalAccuracyPredictor/pyErrorPred/model.py:95)

Input Source operations connected to node 3d_conv/conv3d_1/Conv3D:
 3d_conv/conv3d/Conv3D (defined at home/ajasja/scripts/LocalAccuracyPredictor/pyErrorPred/model.py:95)

Original stack trace for '3d_conv/conv3d_1/Conv3D':
  File "home/ajasja/scripts/LocalAccuracyPredictor/ErrorPredictor.py", line 244, in <module>
    main()
  File "home/ajasja/scripts/LocalAccuracyPredictor/ErrorPredictor.py", line 192, in main
    noEnsemble=args.noEnsemble)
  File "home/ajasja/scripts/LocalAccuracyPredictor/pyErrorPred/predict.py", line 82, in predict
    verbose=False)
  File "home/ajasja/scripts/LocalAccuracyPredictor/pyErrorPred/model.py", line 51, in __init__
    self.ops = self.build()
  File "home/ajasja/scripts/LocalAccuracyPredictor/pyErrorPred/model.py", line 98, in build
    layers.append(tf.layers.conv3d(layers[-1], 20, 3, padding='valid', use_bias=True))
  File "software/conda/envs/tensorflow/lib/python3.6/site-packages/tensorflow/python/util/deprecation.py", line 324, in new_func
    return func(*args, **kwargs)
  File "software/conda/envs/tensorflow/lib/python3.6/site-packages/tensorflow/python/layers/convolutional.py", line 632, in conv3d
    return layer.apply(inputs)
  File "software/conda/envs/tensorflow/lib/python3.6/site-packages/tensorflow/python/keras/engine/base_layer.py", line 1479, in apply
    return self.__call__(inputs, *args, **kwargs)
  File "software/conda/envs/tensorflow/lib/python3.6/site-packages/tensorflow/python/layers/base.py", line 537, in __call__
    outputs = super(Layer, self).__call__(inputs, *args, **kwargs)
  File "software/conda/envs/tensorflow/lib/python3.6/site-packages/tensorflow/python/keras/engine/base_layer.py", line 634, in __call__
    outputs = call_fn(inputs, *args, **kwargs)
  File "software/conda/envs/tensorflow/lib/python3.6/site-packages/tensorflow/python/autograph/impl/api.py", line 146, in wrapper
    ), args, kwargs)
  File "software/conda/envs/tensorflow/lib/python3.6/site-packages/tensorflow/python/autograph/impl/api.py", line 446, in converted_call
    return _call_unconverted(f, args, kwargs)
  File "software/conda/envs/tensorflow/lib/python3.6/site-packages/tensorflow/python/autograph/impl/api.py", line 253, in _call_unconverted
    return f(*args, **kwargs)
  File "software/conda/envs/tensorflow/lib/python3.6/site-packages/tensorflow/python/keras/layers/convolutional.py", line 196, in call
    outputs = self._convolution_op(inputs, self.kernel)
  File "software/conda/envs/tensorflow/lib/python3.6/site-packages/tensorflow/python/ops/nn_ops.py", line 1079, in __call__
    return self.conv_op(inp, filter)
  File "software/conda/envs/tensorflow/lib/python3.6/site-packages/tensorflow/python/ops/nn_ops.py", line 635, in __call__
    return self.call(inp, filter)
  File "software/conda/envs/tensorflow/lib/python3.6/site-packages/tensorflow/python/ops/nn_ops.py", line 234, in __call__
    name=self.name)
  File "software/conda/envs/tensorflow/lib/python3.6/site-packages/tensorflow/python/ops/gen_nn_ops.py", line 1553, in conv3d
    dilations=dilations, name=name)
  File "software/conda/envs/tensorflow/lib/python3.6/site-packages/tensorflow/python/framework/op_def_library.py", line 788, in _apply_op_helper
    op_def=op_def)
  File "software/conda/envs/tensorflow/lib/python3.6/site-packages/tensorflow/python/util/deprecation.py", line 507, in new_func
    return func(*args, **kwargs)
  File "software/conda/envs/tensorflow/lib/python3.6/site-packages/tensorflow/python/framework/ops.py", line 3616, in create_op
    op_def=op_def)
  File "software/conda/envs/tensorflow/lib/python3.6/site-packages/tensorflow/python/framework/ops.py", line 2005, in __init__
    self._traceback = tf_stack.extract_stack()

